2019-03-22 15:12:20,958 -|- INFO -|- 共运行0小时0分钟3秒
2019-03-22 15:35:46,006 -|- ERROR -|- no
Traceback (most recent call last):
  File "g:\稍微正经一点\python-spider\bei_ke_used.py", line 460, in post_email
    smtpObj.login('1650192445@qq.com', 'jyy995817')  # 括号中对应的是发件人邮箱账号、邮箱密码
  File "C:\Python\Python36\lib\smtplib.py", line 730, in login
    raise last_exception
  File "C:\Python\Python36\lib\smtplib.py", line 721, in login
    initial_response_ok=initial_response_ok)
  File "C:\Python\Python36\lib\smtplib.py", line 642, in auth
    raise SMTPAuthenticationError(code, resp)
smtplib.SMTPAuthenticationError: (535, b'Error: \xc7\xeb\xca\xb9\xd3\xc3\xca\xda\xc8\xa8\xc2\xeb\xb5\xc7\xc2\xbc\xa1\xa3\xcf\xea\xc7\xe9\xc7\xeb\xbf\xb4: http://service.mail.qq.com/cgi-bin/help?subtype=1&&id=28&&no=1001256')
2019-03-22 15:38:13,977 -|- ERROR -|- no
Traceback (most recent call last):
  File "g:\稍微正经一点\python-spider\bei_ke_used.py", line 461, in post_email
    smtpObj.sendmail(sender, receivers, message.as_string())
  File "C:\Python\Python36\lib\smtplib.py", line 867, in sendmail
    raise SMTPSenderRefused(code, resp, from_addr)
smtplib.SMTPSenderRefused: (501, b'mail from address must be same as authorization user', 'from@runoob.com')
